INFO:     Will watch for changes in these directories: ['/Users/ryze.ai/Desktop/NR_TAX/backend']
INFO:     Uvicorn running on http://0.0.0.0:8000 (Press CTRL+C to quit)
INFO:     Started reloader process [7688] using StatReload
Process SpawnProcess-1:
Traceback (most recent call last):
  File "/Users/ryze.ai/Desktop/NR_TAX/backend/venv/lib/python3.13/site-packages/pydantic/networks.py", line 925, in import_email_validator
    import email_validator
ModuleNotFoundError: No module named 'email_validator'

The above exception was the direct cause of the following exception:

Traceback (most recent call last):
  File "/opt/homebrew/Cellar/python@3.13/3.13.2/Frameworks/Python.framework/Versions/3.13/lib/python3.13/multiprocessing/process.py", line 313, in _bootstrap
    self.run()
    ~~~~~~~~^^
  File "/opt/homebrew/Cellar/python@3.13/3.13.2/Frameworks/Python.framework/Versions/3.13/lib/python3.13/multiprocessing/process.py", line 108, in run
    self._target(*self._args, **self._kwargs)
    ~~~~~~~~~~~~^^^^^^^^^^^^^^^^^^^^^^^^^^^^^
  File "/Users/ryze.ai/Desktop/NR_TAX/backend/venv/lib/python3.13/site-packages/uvicorn/_subprocess.py", line 80, in subprocess_started
    target(sockets=sockets)
    ~~~~~~^^^^^^^^^^^^^^^^^
  File "/Users/ryze.ai/Desktop/NR_TAX/backend/venv/lib/python3.13/site-packages/uvicorn/server.py", line 66, in run
    return asyncio.run(self.serve(sockets=sockets))
           ~~~~~~~~~~~^^^^^^^^^^^^^^^^^^^^^^^^^^^^^
  File "/opt/homebrew/Cellar/python@3.13/3.13.2/Frameworks/Python.framework/Versions/3.13/lib/python3.13/asyncio/runners.py", line 195, in run
    return runner.run(main)
           ~~~~~~~~~~^^^^^^
  File "/opt/homebrew/Cellar/python@3.13/3.13.2/Frameworks/Python.framework/Versions/3.13/lib/python3.13/asyncio/runners.py", line 118, in run
    return self._loop.run_until_complete(task)
           ~~~~~~~~~~~~~~~~~~~~~~~~~~~~~^^^^^^
  File "/opt/homebrew/Cellar/python@3.13/3.13.2/Frameworks/Python.framework/Versions/3.13/lib/python3.13/asyncio/base_events.py", line 725, in run_until_complete
    return future.result()
           ~~~~~~~~~~~~~^^
  File "/Users/ryze.ai/Desktop/NR_TAX/backend/venv/lib/python3.13/site-packages/uvicorn/server.py", line 70, in serve
    await self._serve(sockets)
  File "/Users/ryze.ai/Desktop/NR_TAX/backend/venv/lib/python3.13/site-packages/uvicorn/server.py", line 77, in _serve
    config.load()
    ~~~~~~~~~~~^^
  File "/Users/ryze.ai/Desktop/NR_TAX/backend/venv/lib/python3.13/site-packages/uvicorn/config.py", line 435, in load
    self.loaded_app = import_from_string(self.app)
                      ~~~~~~~~~~~~~~~~~~^^^^^^^^^^
  File "/Users/ryze.ai/Desktop/NR_TAX/backend/venv/lib/python3.13/site-packages/uvicorn/importer.py", line 19, in import_from_string
    module = importlib.import_module(module_str)
  File "/opt/homebrew/Cellar/python@3.13/3.13.2/Frameworks/Python.framework/Versions/3.13/lib/python3.13/importlib/__init__.py", line 88, in import_module
    return _bootstrap._gcd_import(name[level:], package, level)
           ~~~~~~~~~~~~~~~~~~~~~~^^^^^^^^^^^^^^^^^^^^^^^^^^^^^^
  File "<frozen importlib._bootstrap>", line 1387, in _gcd_import
  File "<frozen importlib._bootstrap>", line 1360, in _find_and_load
  File "<frozen importlib._bootstrap>", line 1331, in _find_and_load_unlocked
  File "<frozen importlib._bootstrap>", line 935, in _load_unlocked
  File "<frozen importlib._bootstrap_external>", line 1026, in exec_module
  File "<frozen importlib._bootstrap>", line 488, in _call_with_frames_removed
  File "/Users/ryze.ai/Desktop/NR_TAX/backend/app/main.py", line 6, in <module>
    from app.routers import auth, users, tax_guides, consultations, faqs
  File "/Users/ryze.ai/Desktop/NR_TAX/backend/app/routers/__init__.py", line 1, in <module>
    from app.routers import auth, users, tax_guides, consultations, faqs
  File "/Users/ryze.ai/Desktop/NR_TAX/backend/app/routers/auth.py", line 7, in <module>
    from app.core.auth import authenticate_user, create_access_token, ACCESS_TOKEN_EXPIRE_MINUTES
  File "/Users/ryze.ai/Desktop/NR_TAX/backend/app/core/auth.py", line 11, in <module>
    from app.schemas.schemas import TokenData
  File "/Users/ryze.ai/Desktop/NR_TAX/backend/app/schemas/__init__.py", line 1, in <module>
    from app.schemas.schemas import User, UserCreate, UserBase, TaxGuide, TaxGuideCreate, TaxGuideBase, Consultation, ConsultationCreate, ConsultationBase, FAQ, FAQCreate, FAQBase, Token, TokenData
  File "/Users/ryze.ai/Desktop/NR_TAX/backend/app/schemas/schemas.py", line 6, in <module>
    class UserBase(BaseModel):
        email: EmailStr
  File "/Users/ryze.ai/Desktop/NR_TAX/backend/venv/lib/python3.13/site-packages/pydantic/_internal/_model_construction.py", line 224, in __new__
    complete_model_class(
    ~~~~~~~~~~~~~~~~~~~~^
        cls,
        ^^^^
    ...<4 lines>...
        create_model_module=_create_model_module,
        ^^^^^^^^^^^^^^^^^^^^^^^^^^^^^^^^^^^^^^^^^
    )
    ^
  File "/Users/ryze.ai/Desktop/NR_TAX/backend/venv/lib/python3.13/site-packages/pydantic/_internal/_model_construction.py", line 602, in complete_model_class
    schema = cls.__get_pydantic_core_schema__(cls, handler)
  File "/Users/ryze.ai/Desktop/NR_TAX/backend/venv/lib/python3.13/site-packages/pydantic/main.py", line 702, in __get_pydantic_core_schema__
    return handler(source)
  File "/Users/ryze.ai/Desktop/NR_TAX/backend/venv/lib/python3.13/site-packages/pydantic/_internal/_schema_generation_shared.py", line 84, in __call__
    schema = self._handler(source_type)
  File "/Users/ryze.ai/Desktop/NR_TAX/backend/venv/lib/python3.13/site-packages/pydantic/_internal/_generate_schema.py", line 610, in generate_schema
    schema = self._generate_schema_inner(obj)
  File "/Users/ryze.ai/Desktop/NR_TAX/backend/venv/lib/python3.13/site-packages/pydantic/_internal/_generate_schema.py", line 879, in _generate_schema_inner
    return self._model_schema(obj)
           ~~~~~~~~~~~~~~~~~~^^^^^
  File "/Users/ryze.ai/Desktop/NR_TAX/backend/venv/lib/python3.13/site-packages/pydantic/_internal/_generate_schema.py", line 691, in _model_schema
    {k: self._generate_md_field_schema(k, v, decorators) for k, v in fields.items()},
        ~~~~~~~~~~~~~~~~~~~~~~~~~~~~~~^^^^^^^^^^^^^^^^^^
  File "/Users/ryze.ai/Desktop/NR_TAX/backend/venv/lib/python3.13/site-packages/pydantic/_internal/_generate_schema.py", line 1071, in _generate_md_field_schema
    common_field = self._common_field_schema(name, field_info, decorators)
  File "/Users/ryze.ai/Desktop/NR_TAX/backend/venv/lib/python3.13/site-packages/pydantic/_internal/_generate_schema.py", line 1263, in _common_field_schema
    schema = self._apply_annotations(
        source_type,
        annotations + validators_from_decorators,
    )
  File "/Users/ryze.ai/Desktop/NR_TAX/backend/venv/lib/python3.13/site-packages/pydantic/_internal/_generate_schema.py", line 2056, in _apply_annotations
    schema = get_inner_schema(source_type)
  File "/Users/ryze.ai/Desktop/NR_TAX/backend/venv/lib/python3.13/site-packages/pydantic/_internal/_schema_generation_shared.py", line 84, in __call__
    schema = self._handler(source_type)
  File "/Users/ryze.ai/Desktop/NR_TAX/backend/venv/lib/python3.13/site-packages/pydantic/_internal/_generate_schema.py", line 2035, in inner_handler
    from_property = self._generate_schema_from_property(obj, source_type)
  File "/Users/ryze.ai/Desktop/NR_TAX/backend/venv/lib/python3.13/site-packages/pydantic/_internal/_generate_schema.py", line 759, in _generate_schema_from_property
    schema = get_schema(
        source, CallbackGetCoreSchemaHandler(self._generate_schema_inner, self, ref_mode=ref_mode)
    )
  File "/Users/ryze.ai/Desktop/NR_TAX/backend/venv/lib/python3.13/site-packages/pydantic/networks.py", line 965, in __get_pydantic_core_schema__
    import_email_validator()
    ~~~~~~~~~~~~~~~~~~~~~~^^
  File "/Users/ryze.ai/Desktop/NR_TAX/backend/venv/lib/python3.13/site-packages/pydantic/networks.py", line 927, in import_email_validator
    raise ImportError('email-validator is not installed, run `pip install pydantic[email]`') from e
ImportError: email-validator is not installed, run `pip install pydantic[email]`
